Workbook

Sheet Model Data
B3: Air Density (kg/m3) | C3: 1.225
B8: Blade Diameter (m) | C8: 7
B9: Area Swet (m2) | C9: =ROUNDUP(PI()*(C8/2)*(C8/2),2) -> 38.49
B10: Rated Voltage (V) | C10: 240
B11: Rated Speed (rad/s) | C11: =(C12*12)/(C8/2) -> 24
B12: Tip-Speed-Ratio | C12: 7
B13: No of Poles | C13: 30
B14: Rated WindSpeed (m/s) | C14: 12

Sheet Power Computed
A1: Wind Speed (m/s) | B1: Cp | C1: Power (Pe) | D1: Rotor Speed (rad/s) | E1: Voltage (V) | F1: Current (A) | G1: Frequency (Hz) | I1: SC Current (A) | J1: OpenCircuit Voltage (Voc)
A2: 2.5 | B2: 0.11 | C2: 39 | D2: =('Model Data'!$C$12*'Power Computed'!A2)/('Model Data'!$C$8/2) -> 5 | E2: =D2*('Model Data'!$C$10/'Model Data'!$C$11) -> 50 | F2: =ROUNDUP((C2/E2),2) -> 0.78 | G2: =ROUNDUP((D2*'Model Data'!$C$13*60)/(120*2*PI()),2) -> 11.94 | I2: =SQRT(C2/$H$29) -> 3.0508812 | J2: =E2+(F2*$H$29) -> 53.2682
A3: 3 | B3: 0.16 | C3: 102 | D3: =('Model Data'!$C$12*'Power Computed'!A3)/('Model Data'!$C$8/2) -> 6 | E3: =D3*('Model Data'!$C$10/'Model Data'!$C$11) -> 60 | F3: =ROUNDUP((C3/E3),2) -> 1.7 | G3: =ROUNDUP((D3*'Model Data'!$C$13*60)/(120*2*PI()),2) -> 14.33 | I3: =SQRT(C3/$H$29) -> 4.933931 | J3: =E3+(F3*$H$29) -> 67.123
A4: 3.5 | B4: 0.23 | C4: 229 | D4: =('Model Data'!$C$12*'Power Computed'!A4)/('Model Data'!$C$8/2) -> 7 | E4: =D4*('Model Data'!$C$10/'Model Data'!$C$11) -> 70 | F4: =ROUNDUP((C4/E4),2) -> 3.28 | G4: =ROUNDUP((D4*'Model Data'!$C$13*60)/(120*2*PI()),2) -> 16.72 | I4: =SQRT(C4/$H$29) -> 7.3928302 | J4: =E4+(F4*$H$29) -> 83.7432
A5: 4 | B5: 0.26 | C5: 399 | D5: =('Model Data'!$C$12*'Power Computed'!A5)/('Model Data'!$C$8/2) -> 8 | E5: =D5*('Model Data'!$C$10/'Model Data'!$C$11) -> 80 | F5: =ROUNDUP((C5/E5),2) -> 4.99 | G5: =ROUNDUP((D5*'Model Data'!$C$13*60)/(120*2*PI()),2) -> 19.1 | I5: =SQRT(C5/$H$29) -> 9.7584184 | J5: =E5+(F5*$H$29) -> 100.9081
A6: 4.5 | B6: 0.28 | C6: 596 | D6: =('Model Data'!$C$12*'Power Computed'!A6)/('Model Data'!$C$8/2) -> 9 | E6: =D6*('Model Data'!$C$10/'Model Data'!$C$11) -> 90 | F6: =ROUNDUP((C6/E6),2) -> 6.63 | G6: =ROUNDUP((D6*'Model Data'!$C$13*60)/(120*2*PI()),2) -> 21.49 | I6: =SQRT(C6/$H$29) -> 11.926585 | J6: =E6+(F6*$H$29) -> 117.7797
A7: 5 | B7: 0.29 | C7: 848 | D7: =('Model Data'!$C$12*'Power Computed'!A7)/('Model Data'!$C$8/2) -> 10 | E7: =D7*('Model Data'!$C$10/'Model Data'!$C$11) -> 100 | F7: =ROUNDUP((C7/E7),2) -> 8.48 | G7: =ROUNDUP((D7*'Model Data'!$C$13*60)/(120*2*PI()),2) -> 23.88 | I7: =SQRT(C7/$H$29) -> 14.226266 | J7: =E7+(F7*$H$29) -> 135.5312
A8: 5.5 | B8: 0.29 | C8: 1151 | D8: =('Model Data'!$C$12*'Power Computed'!A8)/('Model Data'!$C$8/2) -> 11 | E8: =D8*('Model Data'!$C$10/'Model Data'!$C$11) -> 110 | F8: =ROUNDUP((C8/E8),2) -> 10.47 | G8: =ROUNDUP((D8*'Model Data'!$C$13*60)/(120*2*PI()),2) -> 26.27 | I8: =SQRT(C8/$H$29) -> 16.574127 | J8: =E8+(F8*$H$29) -> 153.8693
A9: 6 | B9: 0.3 | C9: 1510 | D9: =('Model Data'!$C$12*'Power Computed'!A9)/('Model Data'!$C$8/2) -> 12 | E9: =D9*('Model Data'!$C$10/'Model Data'!$C$11) -> 120 | F9: =ROUNDUP((C9/E9),2) -> 12.59 | G9: =ROUNDUP((D9*'Model Data'!$C$13*60)/(120*2*PI()),2) -> 28.65 | I9: =SQRT(C9/$H$29) -> 18.983726 | J9: =E9+(F9*$H$29) -> 172.7521
A10: 6.5 | B10: 0.3 | C10: 1938 | D10: =('Model Data'!$C$12*'Power Computed'!A10)/('Model Data'!$C$8/2) -> 13 | E10: =D10*('Model Data'!$C$10/'Model Data'!$C$11) -> 130 | F10: =ROUNDUP((C10/E10),2) -> 14.91 | G10: =ROUNDUP((D10*'Model Data'!$C$13*60)/(120*2*PI()),2) -> 31.04 | I10: =SQRT(C10/$H$29) -> 21.506507 | J10: =E10+(F10*$H$29) -> 192.4729
A11: 7 | B11: 0.3 | C11: 2403 | D11: =('Model Data'!$C$12*'Power Computed'!A11)/('Model Data'!$C$8/2) -> 14 | E11: =D11*('Model Data'!$C$10/'Model Data'!$C$11) -> 140 | F11: =ROUNDUP((C11/E11),2) -> 17.17 | G11: =ROUNDUP((D11*'Model Data'!$C$13*60)/(120*2*PI()),2) -> 33.43 | I11: =SQRT(C11/$H$29) -> 23.948034 | J11: =E11+(F11*$H$29) -> 211.9423
A12: 7.5 | B12: 0.3 | C12: 2949 | D12: =('Model Data'!$C$12*'Power Computed'!A12)/('Model Data'!$C$8/2) -> 15 | E12: =D12*('Model Data'!$C$10/'Model Data'!$C$11) -> 150 | F12: =ROUNDUP((C12/E12),2) -> 19.66 | G12: =ROUNDUP((D12*'Model Data'!$C$13*60)/(120*2*PI()),2) -> 35.81 | I12: =SQRT(C12/$H$29) -> 26.52958 | J12: =E12+(F12*$H$29) -> 232.3754
A13: 8 | B13: 0.3 | C13: 3602 | D13: =('Model Data'!$C$12*'Power Computed'!A13)/('Model Data'!$C$8/2) -> 16 | E13: =D13*('Model Data'!$C$10/'Model Data'!$C$11) -> 160 | F13: =ROUNDUP((C13/E13),2) -> 22.52 | G13: =ROUNDUP((D13*'Model Data'!$C$13*60)/(120*2*PI()),2) -> 38.2 | I13: =SQRT(C13/$H$29) -> 29.320059 | J13: =E13+(F13*$H$29) -> 254.3588
... A27: 15 | B27: 0.16 | C27: 12495 | D27: =('Model Data'!$C$12*'Power Computed'!A27)/('Model Data'!$C$8/2) -> 30 | E27: =D27*('Model Data'!$C$10/'Model Data'!$C$11) -> 300 | F27: =ROUNDUP((C27/E27),2) -> 41.65 | G27: =ROUNDUP((D27*'Model Data'!$C$13*60)/(120*2*PI()),2) -> 71.62 | I27: =SQRT(C27/$H$29) -> 54.60861 | J27: =E27+(F27*$H$29) -> 474.5135
E29: Source Impedance of Turbine | H29: 4.19

Sheet IV Computed
A1: Wind Speed (m/s) | C1: Wind Speed (m/s) | E1: Wind Speed (m/s) | G1: Wind Speed (m/s) | I1: Wind Speed (m/s) | K1: Wind Speed (m/s) | M1: Wind Speed (m/s) | O1: Wind Speed (m/s) | Q1: Wind Speed (m/s) | S1: Wind Speed (m/s) | U1: Wind Speed (m/s) | W1: Wind Speed (m/s) | Y1: Wind Speed (m/s) | AA1: Wind Speed (m/s) | AC1: Wind Speed (m/s) | AE1: Wind Speed (m/s) | AG1: Wind Speed (m/s) | AI1: Wind Speed (m/s) | AK1: Wind Speed (m/s) | AM1: Wind Speed (m/s) | AO1: Wind Speed (m/s) | AQ1: Wind Speed (m/s) | AS1: Wind Speed (m/s) | AU1: Wind Speed (m/s) | AW1: Wind Speed (m/s) | AY1: Wind Speed (m/s)
A2: 2.5 | C2: 3 | E2: 3.5 | G2: 4 | I2: 4.5 | K2: 5 | M2: 5.5 | O2: 6 | Q2: 6.5 | S2: 7 | U2: 7.5 | W2: 8 | Y2: 8.5 | AA2: 9 | AC2: 9.5 | AE2: 10 | AG2: 10.5 | AI2: 11 | AK2: 11.5 | AM2: 12 | AO2: 12.5 | AQ2: 13 | AS2: 13.5 | AU2: 14 | AW2: 14.5 | AY2: 15
A3: Current (A) | B3: Voltage (V) | C3: Current (A) | D3: Voltage (V) | E3: Current (A) | F3: Voltage (V) | G3: Current (A) | H3: Voltage (V) | I3: Current (A) | J3: Voltage (V) | K3: Current (A) | L3: Voltage (V) | M3: Current (A) | N3: Voltage (V) | O3: Current (A) | P3: Voltage (V) | Q3: Current (A) | R3: Voltage (V) | S3: Current (A) | T3: Voltage (V) | U3: Current (A) | V3: Voltage (V) | W3: Current (A) | X3: Voltage (V) | Y3: Current (A) | Z3: Voltage (V) | AA3: Current (A) | AB3: Voltage (V) | AC3: Current (A) | AD3: Voltage (V) | AE3: Current (A) | AF3: Voltage (V) | AG3: Current (A) | AH3: Voltage (V) | AI3: Current (A) | AJ3: Voltage (V) | AK3: Current (A) | AL3: Voltage (V) | AM3: Current (A) | AN3: Voltage (V) | AO3: Current (A) | AP3: Voltage (V) | AQ3: Current (A) | AR3: Voltage (V) | AS3: Current (A) | AT3: Voltage (V) | AU3: Current (A) | AV3: Voltage (V) | AW3: Current (A) | AX3: Voltage (V) | AY3: Current (A) | AZ3: Voltage (V)
A4: 0 | B4: 53.27 | C4: 0 | D4: 67.12 | E4: 0 | F4: 83.74 | G4: 0 | H4: 100.91 | I4: 0 | J4: 117.78 | K4: 0 | L4: 135.53 | M4: 0 | N4: 153.87 | O4: 0 | P4: 172.75 | Q4: 0 | R4: 192.47 | S4: 0 | T4: 211.94 | U4: 0 | V4: 232.38 | W4: 0 | X4: 254.36 | Y4: 0 | Z4: 276.13 | AA4: 0 | AB4: 298.07 | AC4: 0 | AD4: 321.44 | AE4: 0 | AF4: 343.63 | AG4: 0 | AH4: 366.62 | AI4: 0 | AJ4: 388.82 | AK4: 0 | AL4: 410.88 | AM4: 0 | AN4: 430.06 | AO4: 0 | AP4: 444.75 | AQ4: 0 | AR4: 453.7 | AS4: 0 | AT4: 460.52 | AU4: 0 | AV4: 465.49 | AW4: 0 | AX4: 469.88 | AY4: 0 | AZ4: 474.51
A5: 0.1 | B5: 51.55 | C5: 0.1 | D5: 65.75 | E5: 0.1 | F5: 82.61 | G5: 0.1 | H5: 99.88 | I5: 0.1 | J5: 116.79 | K5: 0.1 | L5: 134.58 | M5: 0.1 | N5: 152.94 | O5: 0.1 | P5: 171.84 | Q5: 0.1 | R5: 191.57 | S5: 0.1 | T5: 211.05 | U5: 0.1 | V5: 231.5 | W5: 0.1 | X5: 253.49 | Y5: 0.1 | Z5: 275.27 | AA5: 0.1 | AB5: 297.21 | AC5: 0.1 | AD5: 320.59 | AE5: 0.1 | AF5: 342.78 | AG5: 0.1 | AH5: 365.77 | AI5: 0.1 | AJ5: 387.97 | AK5: 0.1 | AL5: 410.04 | AM5: 0.1 | AN5: 429.22 | AO5: 0.1 | AP5: 443.91 | AQ5: 0.1 | AR5: 452.85 | AS5: 0.1 | AT5: 459.67 | AU5: 0.1 | AV5: 464.63 | AW5: 0.1 | AX5: 469.02 | AY5: 0.1 | AZ5: 473.64
A6: 0.2 | B6: 49.83 | C6: 0.2 | D6: 64.38 | E6: 0.2 | F6: 81.48 | G6: 0.2 | H6: 98.85 | I6: 0.2 | J6: 115.8 | K6: 0.2 | L6: 133.62 | M6: 0.2 | N6: 152.02 | O6: 0.2 | P6: 170.93 | Q6: 0.2 | R6: 190.68 | S6: 0.2 | T6: 210.17 | U6: 0.2 | V6: 230.63 | W6: 0.2 | X6: 252.62 | Y6: 0.2 | Z6: 274.41 | AA6: 0.2 | AB6: 296.36 | AC6: 0.2 | AD6: 319.73 | AE6: 0.2 | AF6: 341.93 | AG6: 0.2 | AH6: 364.93 | AI6: 0.2 | AJ6: 387.13 | AK6: 0.2 | AL6: 409.19 | AM6: 0.2 | AN6: 428.37 | AO6: 0.2 | AP6: 443.06 | AQ6: 0.2 | AR6: 452.01 | AS6: 0.2 | AT6: 458.82 | AU6: 0.2 | AV6: 463.78 | AW6: 0.2 | AX6: 468.16 | AY6: 0.2 | AZ6: 472.77
A7: 0.3 | B7: 48.11 | C7: 0.3 | D7: 63.01 | E7: 0.3 | F7: 80.35 | G7: 0.3 | H7: 97.82 | I7: 0.3 | J7: 114.81 | K7: 0.3 | L7: 132.67 | M7: 0.3 | N7: 151.09 | O7: 0.3 | P7: 170.02 | Q7: 0.3 | R7: 189.78 | S7: 0.3 | T7: 209.28 | U7: 0.3 | V7: 229.75 | W7: 0.3 | X7: 251.76 | Y7: 0.3 | Z7: 273.55 | AA7: 0.3 | AB7: 295.5 | AC7: 0.3 | AD7: 318.88 | AE7: 0.3 | AF7: 341.08 | AG7: 0.3 | AH7: 364.08 | AI7: 0.3 | AJ7: 386.28 | AK7: 0.3 | AL7: 408.35 | AM7: 0.3 | AN7: 427.53 | AO7: 0.3 | AP7: 442.22 | AQ7: 0.3 | AR7: 451.16 | AS7: 0.3 | AT7: 457.97 | AU7: 0.3 | AV7: 462.92 | AW7: 0.3 | AX7: 467.29 | AY7: 0.3 | AZ7: 471.9
A8: 0.4 | B8: 46.4 | C8: 0.4 | D8: 61.64 | E8: 0.4 | F8: 79.21 | G8: 0.4 | H8: 96.79 | I8: 0.4 | J8: 113.82 | K8: 0.4 | L8: 131.71 | M8: 0.4 | N8: 150.16 | O8: 0.4 | P8: 169.11 | Q8: 0.4 | R8: 188.89 | S8: 0.4 | T8: 208.39 | U8: 0.4 | V8: 228.87 | W8: 0.4 | X8: 250.89 | Y8: 0.4 | Z8: 272.69 | AA8: 0.4 | AB8: 294.64 | AC8: 0.4 | AD8: 318.03 | AE8: 0.4 | AF8: 340.24 | AG8: 0.4 | AH8: 363.23 | AI8: 0.4 | AJ8: 385.44 | AK8: 0.4 | AL8: 407.51 | AM8: 0.4 | AN8: 426.69 | AO8: 0.4 | AP8: 441.37 | AQ8: 0.4 | AR8: 450.31 | AS8: 0.4 | AT8: 457.12 | AU8: 0.4 | AV8: 462.07 | AW8: 0.4 | AX8: 466.43 | AY8: 0.4 | AZ8: 471.03
A9: 0.5 | B9: 44.68 | C9: 0.5 | D9: 60.27 | E9: 0.5 | F9: 78.08 | G9: 0.5 | H9: 95.76 | I9: 0.5 | J9: 112.83 | K9: 0.5 | L9: 130.76 | M9: 0.5 | N9: 149.24 | O9: 0.5 | P9: 168.2 | Q9: 0.5 | R9: 187.99 | S9: 0.5 | T9: 207.51 | U9: 0.5 | V9: 228 | W9: 0.5 | X9: 250.02 | Y9: 0.5 | Z9: 271.83 | AA9: 0.5 | AB9: 293.79 | AC9: 0.5 | AD9: 317.18 | AE9: 0.5 | AF9: 339.39 | AG9: 0.5 | AH9: 362.39 | AI9: 0.5 | AJ9: 384.59 | AK9: 0.5 | AL9: 406.66 | AM9: 0.5 | AN9: 425.84 | AO9: 0.5 | AP9: 440.53 | AQ9: 0.5 | AR9: 449.47 | AS9: 0.5 | AT9: 456.26 | AU9: 0.5 | AV9: 461.21 | AW9: 0.5 | AX9: 465.57 | AY9: 0.5 | AZ9: 470.16
A10: 0.6 | B10: 42.96 | C10: 0.6 | D10: 58.9 | E10: 0.6 | F10: 76.95 | G10: 0.6 | H10: 94.73 | I10: 0.6 | J10: 111.84 | K10: 0.6 | L10: 129.8 | M10: 0.6 | N10: 148.31 | O10: 0.6 | P10: 167.29 | Q10: 0.6 | R10: 187.1 | S10: 0.6 | T10: 206.62 | U10: 0.6 | V10: 227.12 | W10: 0.6 | X10: 249.15 | Y10: 0.6 | Z10: 270.97 | AA10: 0.6 | AB10: 292.93 | AC10: 0.6 | AD10: 316.32 | AE10: 0.6 | AF10: 338.54 | AG10: 0.6 | AH10: 361.54 | AI10: 0.6 | AJ10: 383.75 | AK10: 0.6 | AL10: 405.82 | AM10: 0.6 | AN10: 425 | AO10: 0.6 | AP10: 439.69 | AQ10: 0.6 | AR10: 448.62 | AS10: 0.6 | AT10: 455.41 | AU10: 0.6 | AV10: 460.36 | AW10: 0.6 | AX10: 464.71 | AY10: 0.6 | AZ10: 469.3
A11: 0.7 | B11: 41.24 | C11: 0.7 | D11: 57.53 | E11: 0.7 | F11: 75.82 | G11: 0.7 | H11: 93.7 | I11: 0.7 | J11: 110.85 | K11: 0.7 | L11: 128.85 | M11: 0.7 | N11: 147.38 | O11: 0.7 | P11: 166.39 | Q11: 0.7 | R11: 186.2 | S11: 0.7 | T11: 205.73 | U11: 0.7 | V11: 226.24 | W11: 0.7 | X11: 248.28 | Y11: 0.7 | Z11: 270.11 | AA11: 0.7 | AB11: 292.07 | AC11: 0.7 | AD11: 315.47 | AE11: 0.7 | AF11: 337.69 | AG11: 0.7 | AH11: 360.69 | AI11: 0.7 | AJ11: 382.9 | AK11: 0.7 | AL11: 404.97 | AM11: 0.7 | AN11: 424.16 | AO11: 0.7 | AP11: 438.84 | AQ11: 0.7 | AR11: 447.77 | AS11: 0.7 | AT11: 454.56 | AU11: 0.7 | AV11: 459.5 | AW11: 0.7 | AX11: 463.84 | AY11: 0.7 | AZ11: 468.43
A12: 0.8 | B12: 39.52 | C12: 0.8 | D12: 56.16 | E12: 0.8 | F12: 74.69 | G12: 0.8 | H12: 92.67 | I12: 0.8 | J12: 109.86 | K12: 0.8 | L12: 127.89 | M12: 0.8 | N12: 146.45 | O12: 0.8 | P12: 165.48 | Q12: 0.8 | R12: 185.31 | S12: 0.8 | T12: 204.85 | U12: 0.8 | V12: 225.36 | W12: 0.8 | X12: 247.42 | Y12: 0.8 | Z12: 269.25 | AA12: 0.8 | AB12: 291.22 | AC12: 0.8 | AD12: 314.62 | AE12: 0.8 | AF12: 336.84 | AG12: 0.8 | AH12: 359.85 | AI12: 0.8 | AJ12: 382.06 | AK12: 0.8 | AL12: 404.13 | AM12: 0.8 | AN12: 423.31 | AO12: 0.8 | AP12: 438 | AQ12: 0.8 | AR12: 446.93 | AS12: 0.8 | AT12: 453.71 | AU12: 0.8 | AV12: 458.64 | AW12: 0.8 | AX12: 462.98 | AY12: 0.8 | AZ12: 467.56
A13: 0.9 | B13: 37.8 | C13: 0.9 | D13: 54.79 | E13: 0.9 | F13: 73.56 | G13: 0.9 | H13: 91.64 | I13: 0.9 | J13: 108.87 | K13: 0.9 | L13: 126.94 | M13: 0.9 | N13: 145.53 | O13: 0.9 | P13: 164.57 | Q13: 0.9 | R13: 184.41 | S13: 0.9 | T13: 203.96 | U13: 0.9 | V13: 224.49 | W13: 0.9 | X13: 246.55 | Y13: 0.9 | Z13: 268.39 | AA13: 0.9 | AB13: 290.36 | AC13: 0.9 | AD13: 313.77 | AE13: 0.9 | AF13: 335.99 | AG13: 0.9 | AH13: 359 | AI13: 0.9 | AJ13: 381.21 | AK13: 0.9 | AL13: 403.29 | AM13: 0.9 | AN13: 422.47 | AO13: 0.9 | AP13: 437.15 | AQ13: 0.9 | AR13: 446.08 | AS13: 0.9 | AT13: 452.86 | AU13: 0.9 | AV13: 457.79 | AW13: 0.9 | AX13: 462.12 | AY13: 0.9 | AZ13: 466.69
A14: 1 | B14: 36.09 | C14: 1 | D14: 53.42 | E14: 1 | F14: 72.42 | G14: 1 | H14: 90.61 | I14: 1 | J14: 107.88 | K14: 1 | L14: 125.99 | M14: 1 | N14: 144.6 | O14: 1 | P14: 163.66 | Q14: 1 | R14: 183.52 | S14: 1 | T14: 203.07 | U14: 1 | V14: 223.61 | W14: 1 | X14: 245.68 | Y14: 1 | Z14: 267.53 | AA14: 1 | AB14: 289.5 | AC14: 1 | AD14: 312.91 | AE14: 1 | AF14: 335.15 | AG14: 1 | AH14: 358.15 | AI14: 1 | AJ14: 380.37 | AK14: 1 | AL14: 402.44 | AM14: 1 | AN14: 421.63 | AO14: 1 | AP14: 436.31 | AQ14: 1 | AR14: 445.24 | AS14: 1 | AT14: 452.01 | AU14: 1 | AV14: 456.93 | AW14: 1 | AX14: 461.26 | AY14: 1 | AZ14: 465.82
A15: 1.1 | B15: 34.37 | C15: 1.1 | D15: 52.05 | E15: 1.1 | F15: 71.29 | G15: 1.1 | H15: 89.58 | I15: 1.1 | J15: 106.89 | K15: 1.1 | L15: 125.03 | M15: 1.1 | N15: 143.67 | O15: 1.1 | P15: 162.75 | Q15: 1.1 | R15: 182.62 | S15: 1.1 | T15: 202.19 | U15: 1.1 | V15: 222.73 | W15: 1.1 | X15: 244.81 | Y15: 1.1 | Z15: 266.67 | AA15: 1.1 | AB15: 288.65 | AC15: 1.1 | AD15: 312.06 | AE15: 1.1 | AF15: 334.3 | AG15: 1.1 | AH15: 357.31 | AI15: 1.1 | AJ15: 379.52 | AK15: 1.1 | AL15: 401.6 | AM15: 1.1 | AN15: 420.78 | AO15: 1.1 | AP15: 435.47 | AQ15: 1.1 | AR15: 444.39 | AS15: 1.1 | AT15: 451.16 | AU15: 1.1 | AV15: 456.08 | AW15: 1.1 | AX15: 460.4 | AY15: 1.1 | AZ15: 464.95
... A35: 3.1 | B35: 0 | C35: 3.1 | D35: 24.66 | E35: 3.1 | F35: 48.66 | G35: 3.1 | H35: 68.99 | I35: 3.1 | J35: 87.1 | K35: 3.1 | L35: 105.94 | M35: 3.1 | N35: 125.14 | O35: 3.1 | P35: 144.56 | Q35: 3.1 | R35: 164.72 | S35: 3.1 | T35: 184.45 | U35: 3.1 | V35: 205.2 | W35: 3.1 | X35: 227.45 | Y35: 3.1 | Z35: 249.46 | AA35: 3.1 | AB35: 271.52 | AC35: 3.1 | AD35: 295.01 | AE35: 3.1 | AF35: 317.33 | AG35: 3.1 | AH35: 340.37 | AI35: 3.1 | AJ35: 362.62 | AK35: 3.1 | AL35: 384.73 | AM35: 3.1 | AN35: 403.92 | AO35: 3.1 | AP35: 418.59 | AQ35: 3.1 | AR35: 427.46 | AS35: 3.1 | AT35: 434.13 | AU35: 3.1 | AV35: 438.96 | AW35: 3.1 | AX35: 443.15 | AY35: 3.1 | AZ35: 447.57
C36: 3.2 | D36: 23.29 | E36: 3.2 | F36: 47.53 | G36: 3.2 | H36: 67.96 | I36: 3.2 | J36: 86.11 | K36: 3.2 | L36: 104.99 | M36: 3.2 | N36: 124.21 | O36: 3.2 | P36: 143.66 | Q36: 3.2 | R36: 163.82 | S36: 3.2 | T36: 183.56 | U36: 3.2 | V36: 204.32 | W36: 3.2 | X36: 226.58 | Y36: 3.2 | Z36: 248.6 | AA36: 3.2 | AB36: 270.66 | AC36: 3.2 | AD36: 294.16 | AE36: 3.2 | AF36: 316.48 | AG36: 3.2 | AH36: 339.53 | AI36: 3.2 | AJ36: 361.77 | AK36: 3.2 | AL36: 383.88 | AM36: 3.2 | AN36: 403.08 | AO36: 3.2 | AP36: 417.74 | AQ36: 3.2 | AR36: 426.61 | AS36: 3.2 | AT36: 433.28 | AU36: 3.2 | AV36: 438.11 | AW36: 3.2 | AX36: 442.29 | AY36: 3.2 | AZ36: 446.7
C37: 3.3 | D37: 21.92 | E37: 3.3 | F37: 46.4 | G37: 3.3 | H37: 66.93 | I37: 3.3 | J37: 85.12 | K37: 3.3 | L37: 104.03 | M37: 3.3 | N37: 123.28 | O37: 3.3 | P37: 142.75 | Q37: 3.3 | R37: 162.93 | S37: 3.3 | T37: 182.68 | U37: 3.3 | V37: 203.44 | W37: 3.3 | X37: 225.71 | Y37: 3.3 | Z37: 247.74 | AA37: 3.3 | AB37: 269.8 | AC37: 3.3 | AD37: 293.3 | AE37: 3.3 | AF37: 315.63 | AG37: 3.3 | AH37: 338.68 | AI37: 3.3 | AJ37: 360.93 | AK37: 3.3 | AL37: 383.04 | AM37: 3.3 | AN37: 402.23 | AO37: 3.3 | AP37: 416.9 | AQ37: 3.3 | AR37: 425.77 | AS37: 3.3 | AT37: 432.43 | AU37: 3.3 | AV37: 437.25 | AW37: 3.3 | AX37: 441.43 | AY37: 3.3 | AZ37: 445.83
C38: 3.4 | D38: 20.55 | E38: 3.4 | F38: 45.26 | G38: 3.4 | H38: 65.9 | I38: 3.4 | J38: 84.13 | K38: 3.4 | L38: 103.08 | M38: 3.4 | N38: 122.35 | O38: 3.4 | P38: 141.84 | Q38: 3.4 | R38: 162.03 | S38: 3.4 | T38: 181.79 | U38: 3.4 | V38: 202.57 | W38: 3.4 | X38: 224.84 | Y38: 3.4 | Z38: 246.88 | AA38: 3.4 | AB38: 268.95 | AC38: 3.4 | AD38: 292.45 | AE38: 3.4 | AF38: 314.78 | AG38: 3.4 | AH38: 337.83 | AI38: 3.4 | AJ38: 360.08 | AK38: 3.4 | AL38: 382.19 | AM38: 3.4 | AN38: 401.39 | AO38: 3.4 | AP38: 416.06 | AQ38: 3.4 | AR38: 424.92 | AS38: 3.4 | AT38: 431.58 | AU38: 3.4 | AV38: 436.4 | AW38: 3.4 | AX38: 440.57 | AY38: 3.4 | AZ38: 444.96
C39: 3.5 | D39: 19.18 | E39: 3.5 | F39: 44.13 | G39: 3.5 | H39: 64.87 | I39: 3.5 | J39: 83.14 | K39: 3.5 | L39: 102.12 | M39: 3.5 | N39: 121.43 | O39: 3.5 | P39: 140.93 | Q39: 3.5 | R39: 161.14 | S39: 3.5 | T39: 180.9 | U39: 3.5 | V39: 201.69 | W39: 3.5 | X39: 223.98 | Y39: 3.5 | Z39: 246.02 | AA39: 3.5 | AB39: 268.09 | AC39: 3.5 | AD39: 291.6 | AE39: 3.5 | AF39: 313.93 | AG39: 3.5 | AH39: 336.99 | AI39: 3.5 | AJ39: 359.24 | AK39: 3.5 | AL39: 381.35 | AM39: 3.5 | AN39: 400.55 | AO39: 3.5 | AP39: 415.21 | AQ39: 3.5 | AR39: 424.07 | AS39: 3.5 | AT39: 430.73 | AU39: 3.5 | AV39: 435.54 | AW39: 3.5 | AX39: 439.7 | AY39: 3.5 | AZ39: 444.09
C40: 3.6 | D40: 17.81 | E40: 3.6 | F40: 43 | G40: 3.6 | H40: 63.84 | I40: 3.6 | J40: 82.15 | K40: 3.6 | L40: 101.17 | M40: 3.6 | N40: 120.5 | O40: 3.6 | P40: 140.02 | Q40: 3.6 | R40: 160.24 | S40: 3.6 | T40: 180.02 | U40: 3.6 | V40: 200.81 | W40: 3.6 | X40: 223.11 | Y40: 3.6 | Z40: 245.16 | AA40: 3.6 | AB40: 267.24 | AC40: 3.6 | AD40: 290.75 | AE40: 3.6 | AF40: 313.09 | AG40: 3.6 | AH40: 336.14 | AI40: 3.6 | AJ40: 358.39 | AK40: 3.6 | AL40: 380.51 | AM40: 3.6 | AN40: 399.7 | AO40: 3.6 | AP40: 414.37 | AQ40: 3.6 | AR40: 423.23 | AS40: 3.6 | AT40: 429.88 | AU40: 3.6 | AV40: 434.69 | AW40: 3.6 | AX40: 438.84 | AY40: 3.6 | AZ40: 443.22
C41: 3.7 | D41: 16.44 | E41: 3.7 | F41: 41.87 | G41: 3.7 | H41: 62.81 | I41: 3.7 | J41: 81.16 | K41: 3.7 | L41: 100.22 | M41: 3.7 | N41: 119.57 | O41: 3.7 | P41: 139.11 | Q41: 3.7 | R41: 159.35 | S41: 3.7 | T41: 179.13 | U41: 3.7 | V41: 199.93 | W41: 3.7 | X41: 222.24 | Y41: 3.7 | Z41: 244.3 | AA41: 3.7 | AB41: 266.38 | AC41: 3.7 | AD41: 289.89 | AE41: 3.7 | AF41: 312.24 | AG41: 3.7 | AH41: 335.29 | AI41: 3.7 | AJ41: 357.55 | AK41: 3.7 | AL41: 379.66 | AM41: 3.7 | AN41: 398.86 | AO41: 3.7 | AP41: 413.52 | AQ41: 3.7 | AR41: 422.38 | AS41: 3.7 | AT41: 429.02 | AU41: 3.7 | AV41: 433.83 | AW41: 3.7 | AX41: 437.98 | AY41: 3.7 | AZ41: 442.35
C42: 3.8 | D42: 15.07 | E42: 3.8 | F42: 40.74 | G42: 3.8 | H42: 61.78 | I42: 3.8 | J42: 80.17 | K42: 3.8 | L42: 99.26 | M42: 3.8 | N42: 118.65 | O42: 3.8 | P42: 138.2 | Q42: 3.8 | R42: 158.45 | S42: 3.8 | T42: 178.24 | U42: 3.8 | V42: 199.06 | W42: 3.8 | X42: 221.37 | Y42: 3.8 | Z42: 243.44 | AA42: 3.8 | AB42: 265.52 | AC42: 3.8 | AD42: 289.04 | AE42: 3.8 | AF42: 311.39 | AG42: 3.8 | AH42: 334.45 | AI42: 3.8 | AJ42: 356.7 | AK42: 3.8 | AL42: 378.82 | AM42: 3.8 | AN42: 398.02 | AO42: 3.8 | AP42: 412.68 | AQ42: 3.8 | AR42: 421.53 | AS42: 3.8 | AT42: 428.17 | AU42: 3.8 | AV42: 432.97 | AW42: 3.8 | AX42: 437.12 | AY42: 3.8 | AZ42: 441.49
C43: 3.9 | D43: 13.7 | E43: 3.9 | F43: 39.61 | G43: 3.9 | H43: 60.75 | I43: 3.9 | J43: 79.18 | K43: 3.9 | L43: 98.31 | M43: 3.9 | N43: 117.72 | O43: 3.9 | P43: 137.29 | Q43: 3.9 | R43: 157.56 | S43: 3.9 | T43: 177.36 | U43: 3.9 | V43: 198.18 | W43: 3.9 | X43: 220.5 | Y43: 3.9 | Z43: 242.58 | AA43: 3.9 | AB43: 264.67 | AC43: 3.9 | AD43: 288.19 | AE43: 3.9 | AF43: 310.54 | AG43: 3.9 | AH43: 333.6 | AI43: 3.9 | AJ43: 355.85 | AK43: 3.9 | AL43: 377.98 | AM43: 3.9 | AN43: 397.17 | AO43: 3.9 | AP43: 411.84 | AQ43: 3.9 | AR43: 420.69 | AS43: 3.9 | AT43: 427.32 | AU43: 3.9 | AV43: 432.12 | AW43: 3.9 | AX43: 436.26 | AY43: 3.9 | AZ43: 440.62
C44: 4 | D44: 12.33 | E44: 4 | F44: 38.48 | G44: 4 | H44: 59.72 | I44: 4 | J44: 78.19 | K44: 4 | L44: 97.35 | M44: 4 | N44: 116.79 | O44: 4 | P44: 136.38 | Q44: 4 | R44: 156.66 | S44: 4 | T44: 176.47 | U44: 4 | V44: 197.3 | W44: 4 | X44: 219.64 | Y44: 4 | Z44: 241.72 | AA44: 4 | AB44: 263.81 | AC44: 4 | AD44: 287.33 | AE44: 4 | AF44: 309.69 | AG44: 4 | AH44: 332.75 | AI44: 4 | AJ44: 355.01 | AK44: 4 | AL44: 377.13 | AM44: 4 | AN44: 396.33 | AO44: 4 | AP44: 410.99 | AQ44: 4 | AR44: 419.84 | AS44: 4 | AT44: 426.47 | AU44: 4 | AV44: 431.26 | AW44: 4 | AX44: 435.39 | AY44: 4 | AZ44: 439.75
C45: 4.1 | D45: 10.96 | E45: 4.1 | F45: 37.34 | G45: 4.1 | H45: 58.69 | I45: 4.1 | J45: 77.2 | K45: 4.1 | L45: 96.4 | M45: 4.1 | N45: 115.87 | O45: 4.1 | P45: 135.47 | Q45: 4.1 | R45: 155.77 | S45: 4.1 | T45: 175.58 | U45: 4.1 | V45: 196.43 | W45: 4.1 | X45: 218.77 | Y45: 4.1 | Z45: 240.86 | AA45: 4.1 | AB45: 262.95 | AC45: 4.1 | AD45: 286.48 | AE45: 4.1 | AF45: 308.84 | AG45: 4.1 | AH45: 331.91 | AI45: 4.1 | AJ45: 354.16 | AK45: 4.1 | AL45: 376.29 | AM45: 4.1 | AN45: 395.49 | AO45: 4.1 | AP45: 410.15 | AQ45: 4.1 | AR45: 419 | AS45: 4.1 | AT45: 425.62 | AU45: 4.1 | AV45: 430.41 | AW45: 4.1 | AX45: 434.53 | AY45: 4.1 | AZ45: 438.88
C46: 4.2 | D46: 9.59 | E46: 4.2 | F46: 36.21 | G46: 4.2 | H46: 57.66 | I46: 4.2 | J46: 76.21 | K46: 4.2 | L46: 95.44 | M46: 4.2 | N46: 114.94 | O46: 4.2 | P46: 134.56 | Q46: 4.2 | R46: 154.87 | S46: 4.2 | T46: 174.7 | U46: 4.2 | V46: 195.55 | W46: 4.2 | X46: 217.9 | Y46: 4.2 | Z46: 240 | AA46: 4.2 | AB46: 262.1 | AC46: 4.2 | AD46: 285.63 | AE46: 4.2 | AF46: 307.99 | AG46: 4.2 | AH46: 331.06 | AI46: 4.2 | AJ46: 353.32 | AK46: 4.2 | AL46: 375.44 | AM46: 4.2 | AN46: 394.64 | AO46: 4.2 | AP46: 409.31 | AQ46: 4.2 | AR46: 418.15 | AS46: 4.2 | AT46: 424.77 | AU46: 4.2 | AV46: 429.55 | AW46: 4.2 | AX46: 433.67 | AY46: 4.2 | AZ46: 438.01
C47: 4.3 | D47: 8.22 | E47: 4.3 | F47: 35.08 | G47: 4.3 | H47: 56.63 | I47: 4.3 | J47: 75.22 | K47: 4.3 | L47: 94.49 | M47: 4.3 | N47: 114.01 | O47: 4.3 | P47: 133.65 | Q47: 4.3 | R47: 153.98 | S47: 4.3 | T47: 173.81 | U47: 4.3 | V47: 194.67 | W47: 4.3 | X47: 217.03 | Y47: 4.3 | Z47: 239.14 | AA47: 4.3 | AB47: 261.24 | AC47: 4.3 | AD47: 284.78 | AE47: 4.3 | AF47: 307.15 | AG47: 4.3 | AH47: 330.21 | AI47: 4.3 | AJ47: 352.47 | AK47: 4.3 | AL47: 374.6 | AM47: 4.3 | AN47: 393.8 | AO47: 4.3 | AP47: 408.46 | AQ47: 4.3 | AR47: 417.3 | AS47: 4.3 | AT47: 423.92 | AU47: 4.3 | AV47: 428.7 | AW47: 4.3 | AX47: 432.81 | AY47: 4.3 | AZ47: 437.14
... C53: 4.9 | D53: 0 | E53: 4.9 | F53: 28.29 | G53: 4.9 | H53: 50.46 | I53: 4.9 | J53: 69.28 | K53: 4.9 | L53: 88.76 | M53: 4.9 | N53: 108.45 | O53: 4.9 | P53: 128.2 | Q53: 4.9 | R53: 148.6 | S53: 4.9 | T53: 168.49 | U53: 4.9 | V53: 189.41 | W53: 4.9 | X53: 211.82 | Y53: 4.9 | Z53: 233.98 | AA53: 4.9 | AB53: 256.1 | AC53: 4.9 | AD53: 279.66 | AE53: 4.9 | AF53: 302.06 | AG53: 4.9 | AH53: 325.13 | AI53: 4.9 | AJ53: 347.4 | AK53: 4.9 | AL53: 369.54 | AM53: 4.9 | AN53: 388.74 | AO53: 4.9 | AP53: 403.4 | AQ53: 4.9 | AR53: 412.22 | AS53: 4.9 | AT53: 418.81 | AU53: 4.9 | AV53: 423.56 | AW53: 4.9 | AX53: 427.63 | AY53: 4.9 | AZ53: 431.93
E54: 5 | F54: 27.16 | G54: 5 | H54: 49.43 | I54: 5 | J54: 68.29 | K54: 5 | L54: 87.81 | M54: 5 | N54: 107.52 | O54: 5 | P54: 127.29 | Q54: 5 | R54: 147.71 | S54: 5 | T54: 167.6 | U54: 5 | V54: 188.53 | W54: 5 | X54: 210.95 | Y54: 5 | Z54: 233.12 | AA54: 5 | AB54: 255.24 | AC54: 5 | AD54: 278.81 | AE54: 5 | AF54: 301.21 | AG54: 5 | AH54: 324.29 | AI54: 5 | AJ54: 346.56 | AK54: 5 | AL54: 368.7 | AM54: 5 | AN54: 387.9 | AO54: 5 | AP54: 402.55 | AQ54: 5 | AR54: 411.38 | AS54: 5 | AT54: 417.96 | AU54: 5 | AV54: 422.71 | AW54: 5 | AX54: 426.77 | AY54: 5 | AZ54: 431.06
E55: 5.1 | F55: 26.03 | G55: 5.1 | H55: 48.4 | I55: 5.1 | J55: 67.3 | K55: 5.1 | L55: 86.85 | M55: 5.1 | N55: 106.6 | O55: 5.1 | P55: 126.38 | Q55: 5.1 | R55: 146.81 | S55: 5.1 | T55: 166.71 | U55: 5.1 | V55: 187.66 | W55: 5.1 | X55: 210.09 | Y55: 5.1 | Z55: 232.26 | AA55: 5.1 | AB55: 254.39 | AC55: 5.1 | AD55: 277.96 | AE55: 5.1 | AF55: 300.36 | AG55: 5.1 | AH55: 323.44 | AI55: 5.1 | AJ55: 345.71 | AK55: 5.1 | AL55: 367.85 | AM55: 5.1 | AN55: 387.05 | AO55: 5.1 | AP55: 401.71 | AQ55: 5.1 | AR55: 410.53 | AS55: 5.1 | AT55: 417.11 | AU55: 5.1 | AV55: 421.85 | AW55: 5.1 | AX55: 425.91 | AY55: 5.1 | AZ55: 430.19
E56: 5.2 | F56: 24.9 | G56: 5.2 | H56: 47.37 | I56: 5.2 | J56: 66.31 | K56: 5.2 | L56: 85.9 | M56: 5.2 | N56: 105.67 | O56: 5.2 | P56: 125.47 | Q56: 5.2 | R56: 145.92 | S56: 5.2 | T56: 165.83 | U56: 5.2 | V56: 186.78 | W56: 5.2 | X56: 209.22 | Y56: 5.2 | Z56: 231.4 | AA56: 5.2 | AB56: 253.53 | AC56: 5.2 | AD56: 277.1 | AE56: 5.2 | AF56: 299.51 | AG56: 5.2 | AH56: 322.59 | AI56: 5.2 | AJ56: 344.87 | AK56: 5.2 | AL56: 367.01 | AM56: 5.2 | AN56: 386.21 | AO56: 5.2 | AP56: 400.87 | AQ56: 5.2 | AR56: 409.68 | AS56: 5.2 | AT56: 416.26 | AU56: 5.2 | AV56: 420.99 | AW56: 5.2 | AX56: 425.05 | AY56: 5.2 | AZ56: 429.32
E57: 5.3 | F57: 23.76 | G57: 5.3 | H57: 46.34 | I57: 5.3 | J57: 65.32 | K57: 5.3 | L57: 84.94 | M57: 5.3 | N57: 104.74 | O57: 5.3 | P57: 124.56 | Q57: 5.3 | R57: 145.02 | S57: 5.3 | T57: 164.94 | U57: 5.3 | V57: 185.9 | W57: 5.3 | X57: 208.35 | Y57: 5.3 | Z57: 230.54 | AA57: 5.3 | AB57: 252.67 | AC57: 5.3 | AD57: 276.25 | AE57: 5.3 | AF57: 298.66 | AG57: 5.3 | AH57: 321.75 | AI57: 5.3 | AJ57: 344.02 | AK57: 5.3 | AL57: 366.16 | AM57: 5.3 | AN57: 385.37 | AO57: 5.3 | AP57: 400.02 | AQ57: 5.3 | AR57: 408.84 | AS57: 5.3 | AT57: 415.4 | AU57: 5.3 | AV57: 420.14 | AW57: 5.3 | AX57: 424.19 | AY57: 5.3 | AZ57: 428.45
E58: 5.4 | F58: 22.63 | G58: 5.4 | H58: 45.31 | I58: 5.4 | J58: 64.33 | K58: 5.4 | L58: 83.99 | M58: 5.4 | N58: 103.82 | O58: 5.4 | P58: 123.65 | Q58: 5.4 | R58: 144.13 | S58: 5.4 | T58: 164.05 | U58: 5.4 | V58: 185.03 | W58: 5.4 | X58: 207.48 | Y58: 5.4 | Z58: 229.68 | AA58: 5.4 | AB58: 251.82 | AC58: 5.4 | AD58: 275.4 | AE58: 5.4 | AF58: 297.81 | AG58: 5.4 | AH58: 320.9 | AI58: 5.4 | AJ58: 343.18 | AK58: 5.4 | AL58: 365.32 | AM58: 5.4 | AN58: 384.52 | AO58: 5.4 | AP58: 399.18 | AQ58: 5.4 | AR58: 407.99 | AS58: 5.4 | AT58: 414.55 | AU58: 5.4 | AV58: 419.28 | AW58: 5.4 | AX58: 423.32 | AY58: 5.4 | AZ58: 427.58
E59: 5.5 | F59: 21.5 | G59: 5.5 | H59: 44.28 | I59: 5.5 | J59: 63.34 | K59: 5.5 | L59: 83.04 | M59: 5.5 | N59: 102.89 | O59: 5.5 | P59: 122.74 | Q59: 5.5 | R59: 143.23 | S59: 5.5 | T59: 163.17 | U59: 5.5 | V59: 184.15 | W59: 5.5 | X59: 206.61 | Y59: 5.5 | Z59: 228.82 | AA59: 5.5 | AB59: 250.96 | AC59: 5.5 | AD59: 274.55 | AE59: 5.5 | AF59: 296.96 | AG59: 5.5 | AH59: 320.05 | AI59: 5.5 | AJ59: 342.33 | AK59: 5.5 | AL59: 364.48 | AM59: 5.5 | AN59: 383.68 | AO59: 5.5 | AP59: 398.33 | AQ59: 5.5 | AR59: 407.14 | AS59: 5.5 | AT59: 413.7 | AU59: 5.5 | AV59: 418.43 | AW59: 5.5 | AX59: 422.46 | AY59: 5.5 | AZ59: 426.71
E60: 5.6 | F60: 20.37 | G60: 5.6 | H60: 43.25 | I60: 5.6 | J60: 62.35 | K60: 5.6 | L60: 82.08 | M60: 5.6 | N60: 101.96 | O60: 5.6 | P60: 121.83 | Q60: 5.6 | R60: 142.34 | S60: 5.6 | T60: 162.28 | U60: 5.6 | V60: 183.27 | W60: 5.6 | X60: 205.75 | Y60: 5.6 | Z60: 227.96 | AA60: 5.6 | AB60: 250.1 | AC60: 5.6 | AD60: 273.69 | AE60: 5.6 | AF60: 296.12 | AG60: 5.6 | AH60: 319.2 | AI60: 5.6 | AJ60: 341.49 | AK60: 5.6 | AL60: 363.63 | AM60: 5.6 | AN60: 382.84 | AO60: 5.6 | AP60: 397.49 | AQ60: 5.6 | AR60: 406.3 | AS60: 5.6 | AT60: 412.85 | AU60: 5.6 | AV60: 417.57 | AW60: 5.6 | AX60: 421.6 | AY60: 5.6 | AZ60: 425.84
E61: 5.7 | F61: 19.24 | G61: 5.7 | H61: 42.22 | I61: 5.7 | J61: 61.36 | K61: 5.7 | L61: 81.13 | M61: 5.7 | N61: 101.04 | O61: 5.7 | P61: 120.92 | Q61: 5.7 | R61: 141.44 | S61: 5.7 | T61: 161.39 | U61: 5.7 | V61: 182.4 | W61: 5.7 | X61: 204.88 | Y61: 5.7 | Z61: 227.1 | AA61: 5.7 | AB61: 249.25 | AC61: 5.7 | AD61: 272.84 | AE61: 5.7 | AF61: 295.27 | AG61: 5.7 | AH61: 318.36 | AI61: 5.7 | AJ61: 340.64 | AK61: 5.7 | AL61: 362.79 | AM61: 5.7 | AN61: 381.99 | AO61: 5.7 | AP61: 396.65 | AQ61: 5.7 | AR61: 405.45 | AS61: 5.7 | AT61: 412 | AU61: 5.7 | AV61: 416.72 | AW61: 5.7 | AX61: 420.74 | AY61: 5.7 | AZ61: 424.97
E62: 5.8 | F62: 18.11 | G62: 5.8 | H62: 41.19 | I62: 5.8 | J62: 60.37 | K62: 5.8 | L62: 80.17 | M62: 5.8 | N62: 100.11 | O62: 5.8 | P62: 120.02 | Q62: 5.8 | R62: 140.55 | S62: 5.8 | T62: 160.51 | U62: 5.8 | V62: 181.52 | W62: 5.8 | X62: 204.01 | Y62: 5.8 | Z62: 226.24 | AA62: 5.8 | AB62: 248.39 | AC62: 5.8 | AD62: 271.99 | AE62: 5.8 | AF62: 294.42 | AG62: 5.8 | AH62: 317.51 | AI62: 5.8 | AJ62: 339.79 | AK62: 5.8 | AL62: 361.95 | AM62: 5.8 | AN62: 381.15 | AO62: 5.8 | AP62: 395.8 | AQ62: 5.8 | AR62: 404.61 | AS62: 5.8 | AT62: 411.15 | AU62: 5.8 | AV62: 415.86 | AW62: 5.8 | AX62: 419.87 | AY62: 5.8 | AZ62: 424.1
E63: 5.9 | F63: 16.97 | G63: 5.9 | H63: 40.16 | I63: 5.9 | J63: 59.38 | K63: 5.9 | L63: 79.22 | M63: 5.9 | N63: 99.18 | O63: 5.9 | P63: 119.11 | Q63: 5.9 | R63: 139.65 | S63: 5.9 | T63: 159.62 | U63: 5.9 | V63: 180.64 | W63: 5.9 | X63: 203.14 | Y63: 5.9 | Z63: 225.38 | AA63: 5.9 | AB63: 247.54 | AC63: 5.9 | AD63: 271.14 | AE63: 5.9 | AF63: 293.57 | AG63: 5.9 | AH63: 316.66 | AI63: 5.9 | AJ63: 338.95 | AK63: 5.9 | AL63: 361.1 | AM63: 5.9 | AN63: 380.31 | AO63: 5.9 | AP63: 394.96 | AQ63: 5.9 | AR63: 403.76 | AS63: 5.9 | AT63: 410.3 | AU63: 5.9 | AV63: 415 | AW63: 5.9 | AX63: 419.01 | AY63: 5.9 | AZ63: 423.24
E64: 6 | F64: 15.84 | G64: 6 | H64: 39.13 | I64: 6 | J64: 58.4 | K64: 6 | L64: 78.26 | M64: 6 | N64: 98.25 | O64: 6 | P64: 118.2 | Q64: 6 | R64: 138.76 | S64: 6 | T64: 158.73 | U64: 6 | V64: 179.77 | W64: 6 | X64: 202.27 | Y64: 6 | Z64: 224.52 | AA64: 6 | AB64: 246.68 | AC64: 6 | AD64: 270.28 | AE64: 6 | AF64: 292.72 | AG64: 6 | AH64: 315.82 | AI64: 6 | AJ64: 338.1 | AK64: 6 | AL64: 360.26 | AM64: 6 | AN64: 379.46 | AO64: 6 | AP64: 394.11 | AQ64: 6 | AR64: 402.91 | AS64: 6 | AT64: 409.45 | AU64: 6 | AV64: 414.15 | AW64: 6 | AX64: 418.15 | AY64: 6 | AZ64: 422.37
...

Sheet PV Computed
A1: 2.5 | C1: 3 | E1: 3.5 | G1: 4 | I1: 4.5 | K1: 5 | M1: 5.5 | O1: 6 | Q1: 6.5 | S1: 7 | U1: 7.5 | W1: 8 | Y1: 8.5 | AA1: 9 | AC1: 9.5 | AE1: 10 | AG1: 10.5 | AI1: 11 | AK1: 11.5 | AM1: 12 | AO1: 12.5 | AQ1: 13 | AS1: 13.5 | AU1: 14 | AW1: 14.5 | AY1: 15
A2: ='IV Computed'!B4 -> 53.27 | B2: ='IV Computed'!B4*'IV Computed'!A4 -> 0 | C2: ='IV Computed'!D4 -> 67.12 | D2: ='IV Computed'!D4*'IV Computed'!C4 -> 0 | E2: ='IV Computed'!F4 -> 83.74 | F2: ='IV Computed'!F4*'IV Computed'!E4 -> 0 | G2: ='IV Computed'!H4 -> 100.91 | H2: ='IV Computed'!H4*'IV Computed'!G4 -> 0 | I2: ='IV Computed'!J4 -> 117.78 | J2: ='IV Computed'!J4*'IV Computed'!I4 -> 0 | K2: ='IV Computed'!L4 -> 135.53 | L2: ='IV Computed'!L4*'IV Computed'!K4 -> 0 | M2: ='IV Computed'!N4 -> 153.87 | N2: ='IV Computed'!N4*'IV Computed'!M4 -> 0 | O2: ='IV Computed'!P4 -> 172.75 | P2: ='IV Computed'!P4*'IV Computed'!O4 -> 0 | Q2: ='IV Computed'!R4 -> 192.47 | R2: ='IV Computed'!R4*'IV Computed'!Q4 -> 0 | S2: ='IV Computed'!T4 -> 211.94 | T2: ='IV Computed'!T4*'IV Computed'!S4 -> 0 | U2: ='IV Computed'!V4 -> 232.38 | V2: ='IV Computed'!V4*'IV Computed'!U4 -> 0 | W2: ='IV Computed'!X4 -> 254.36 | X2: ='IV Computed'!X4*'IV Computed'!W4 -> 0 | Y2: ='IV Computed'!Z4 -> 276.13 | Z2: ='IV Computed'!Z4*'IV Computed'!Y4 -> 0 | AA2: ='IV Computed'!AB4 -> 298.07 | AB2: ='IV Computed'!AB4*'IV Computed'!AA4 -> 0 | AC2: ='IV Computed'!AD4 -> 321.44 | AD2: ='IV Computed'!AD4*'IV Computed'!AC4 -> 0 | AE2: ='IV Computed'!AF4 -> 343.63 | AF2: ='IV Computed'!AF4*'IV Computed'!AE4 -> 0 | AG2: ='IV Computed'!AH4 -> 366.62 | AH2: ='IV Computed'!AH4*'IV Computed'!AG4 -> 0 | AI2: ='IV Computed'!AJ4 -> 388.82 | AJ2: ='IV Computed'!AJ4*'IV Computed'!AI4 -> 0 | AK2: ='IV Computed'!AL4 -> 410.88 | AL2: ='IV Computed'!AL4*'IV Computed'!AK4 -> 0 | AM2: ='IV Computed'!AN4 -> 430.06 | AN2: ='IV Computed'!AN4*'IV Computed'!AM4 -> 0 | AO2: ='IV Computed'!AP4 -> 444.75 | AP2: ='IV Computed'!AP4*'IV Computed'!AO4 -> 0 | AQ2: ='IV Computed'!AR4 -> 453.7 | AR2: ='IV Computed'!AR4*'IV Computed'!AQ4 -> 0 | AS2: ='IV Computed'!AT4 -> 460.52 | AT2: ='IV Computed'!AT4*'IV Computed'!AS4 -> 0 | AU2: ='IV Computed'!AV4 -> 465.49 | AV2: ='IV Computed'!AV4*'IV Computed'!AU4 -> 0 | AW2: ='IV Computed'!AX4 -> 469.88 | AX2: ='IV Computed'!AX4*'IV Computed'!AW4 -> 0 | AY2: ='IV Computed'!AZ4 -> 474.51 | AZ2: ='IV Computed'!AZ4*'IV Computed'!AY4 -> 0
A3: ='IV Computed'!B5 -> 51.55 | B3: ='IV Computed'!B5*'IV Computed'!A5 -> 5.155 | C3: ='IV Computed'!D5 -> 65.75 | D3: ='IV Computed'!D5*'IV Computed'!C5 -> 6.575 | E3: ='IV Computed'!F5 -> 82.61 | F3: ='IV Computed'!F5*'IV Computed'!E5 -> 8.261 | G3: ='IV Computed'!H5 -> 99.88 | H3: ='IV Computed'!H5*'IV Computed'!G5 -> 9.988 | I3: ='IV Computed'!J5 -> 116.79 | J3: ='IV Computed'!J5*'IV Computed'!I5 -> 11.679 | K3: ='IV Computed'!L5 -> 134.58 | L3: ='IV Computed'!L5*'IV Computed'!K5 -> 13.458 | M3: ='IV Computed'!N5 -> 152.94 | N3: ='IV Computed'!N5*'IV Computed'!M5 -> 15.294 | O3: ='IV Computed'!P5 -> 171.84 | P3: ='IV Computed'!P5*'IV Computed'!O5 -> 17.184 | Q3: ='IV Computed'!R5 -> 191.57 | R3: ='IV Computed'!R5*'IV Computed'!Q5 -> 19.157 | S3: ='IV Computed'!T5 -> 211.05 | T3: ='IV Computed'!T5*'IV Computed'!S5 -> 21.105 | U3: ='IV Computed'!V5 -> 231.5 | V3: ='IV Computed'!V5*'IV Computed'!U5 -> 23.15 | W3: ='IV Computed'!X5 -> 253.49 | X3: ='IV Computed'!X5*'IV Computed'!W5 -> 25.349 | Y3: ='IV Computed'!Z5 -> 275.27 | Z3: ='IV Computed'!Z5*'IV Computed'!Y5 -> 27.527 | AA3: ='IV Computed'!AB5 -> 297.21 | AB3: ='IV Computed'!AB5*'IV Computed'!AA5 -> 29.721 | AC3: ='IV Computed'!AD5 -> 320.59 | AD3: ='IV Computed'!AD5*'IV Computed'!AC5 -> 32.059 | AE3: ='IV Computed'!AF5 -> 342.78 | AF3: ='IV Computed'!AF5*'IV Computed'!AE5 -> 34.278 | AG3: ='IV Computed'!AH5 -> 365.77 | AH3: ='IV Computed'!AH5*'IV Computed'!AG5 -> 36.577 | AI3: ='IV Computed'!AJ5 -> 387.97 | AJ3: ='IV Computed'!AJ5*'IV Computed'!AI5 -> 38.797 | AK3: ='IV Computed'!AL5 -> 410.04 | AL3: ='IV Computed'!AL5*'IV Computed'!AK5 -> 41.004 | AM3: ='IV Computed'!AN5 -> 429.22 | AN3: ='IV Computed'!AN5*'IV Computed'!AM5 -> 42.922 | AO3: ='IV Computed'!AP5 -> 443.91 | AP3: ='IV Computed'!AP5*'IV Computed'!AO5 -> 44.391 | AQ3: ='IV Computed'!AR5 -> 452.85 | AR3: ='IV Computed'!AR5*'IV Computed'!AQ5 -> 45.285 | AS3: ='IV Computed'!AT5 -> 459.67 | AT3: ='IV Computed'!AT5*'IV Computed'!AS5 -> 45.967 | AU3: ='IV Computed'!AV5 -> 464.63 | AV3: ='IV Computed'!AV5*'IV Computed'!AU5 -> 46.463 | AW3: ='IV Computed'!AX5 -> 469.02 | AX3: ='IV Computed'!AX5*'IV Computed'!AW5 -> 46.902 | AY3: ='IV Computed'!AZ5 -> 473.64 | AZ3: ='IV Computed'!AZ5*'IV Computed'!AY5 -> 47.364 | BD3: 0 | BE3: 0
A4: ='IV Computed'!B6 -> 49.83 | B4: ='IV Computed'!B6*'IV Computed'!A6 -> 9.966 | C4: ='IV Computed'!D6 -> 64.38 | D4: ='IV Computed'!D6*'IV Computed'!C6 -> 12.876 | E4: ='IV Computed'!F6 -> 81.48 | F4: ='IV Computed'!F6*'IV Computed'!E6 -> 16.296 | G4: ='IV Computed'!H6 -> 98.85 | H4: ='IV Computed'!H6*'IV Computed'!G6 -> 19.77 | I4: ='IV Computed'!J6 -> 115.8 | J4: ='IV Computed'!J6*'IV Computed'!I6 -> 23.16 | K4: ='IV Computed'!L6 -> 133.62 | L4: ='IV Computed'!L6*'IV Computed'!K6 -> 26.724 | M4: ='IV Computed'!N6 -> 152.02 | N4: ='IV Computed'!N6*'IV Computed'!M6 -> 30.404 | O4: ='IV Computed'!P6 -> 170.93 | P4: ='IV Computed'!P6*'IV Computed'!O6 -> 34.186 | Q4: ='IV Computed'!R6 -> 190.68 | R4: ='IV Computed'!R6*'IV Computed'!Q6 -> 38.136 | S4: ='IV Computed'!T6 -> 210.17 | T4: ='IV Computed'!T6*'IV Computed'!S6 -> 42.034 | U4: ='IV Computed'!V6 -> 230.63 | V4: ='IV Computed'!V6*'IV Computed'!U6 -> 46.126 | W4: ='IV Computed'!X6 -> 252.62 | X4: ='IV Computed'!X6*'IV Computed'!W6 -> 50.524 | Y4: ='IV Computed'!Z6 -> 274.41 | Z4: ='IV Computed'!Z6*'IV Computed'!Y6 -> 54.882 | AA4: ='IV Computed'!AB6 -> 296.36 | AB4: ='IV Computed'!AB6*'IV Computed'!AA6 -> 59.272 | AC4: ='IV Computed'!AD6 -> 319.73 | AD4: ='IV Computed'!AD6*'IV Computed'!AC6 -> 63.946 | AE4: ='IV Computed'!AF6 -> 341.93 | AF4: ='IV Computed'!AF6*'IV Computed'!AE6 -> 68.386 | AG4: ='IV Computed'!AH6 -> 364.93 | AH4: ='IV Computed'!AH6*'IV Computed'!AG6 -> 72.986 | AI4: ='IV Computed'!AJ6 -> 387.13 | AJ4: ='IV Computed'!AJ6*'IV Computed'!AI6 -> 77.426 | AK4: ='IV Computed'!AL6 -> 409.19 | AL4: ='IV Computed'!AL6*'IV Computed'!AK6 -> 81.838 | AM4: ='IV Computed'!AN6 -> 428.37 | AN4: ='IV Computed'!AN6*'IV Computed'!AM6 -> 85.674 | AO4: ='IV Computed'!AP6 -> 443.06 | AP4: ='IV Computed'!AP6*'IV Computed'!AO6 -> 88.612 | AQ4: ='IV Computed'!AR6 -> 452.01 | AR4: ='IV Computed'!AR6*'IV Computed'!AQ6 -> 90.402 | AS4: ='IV Computed'!AT6 -> 458.82 | AT4: ='IV Computed'!AT6*'IV Computed'!AS6 -> 91.764 | AU4: ='IV Computed'!AV6 -> 463.78 | AV4: ='IV Computed'!AV6*'IV Computed'!AU6 -> 92.756 | AW4: ='IV Computed'!AX6 -> 468.16 | AX4: ='IV Computed'!AX6*'IV Computed'!AW6 -> 93.632 | AY4: ='IV Computed'!AZ6 -> 472.77 | AZ4: ='IV Computed'!AZ6*'IV Computed'!AY6 -> 94.554 | BC4: 2.5 | BD4: 25.78 | BE4: =MAX(B2:B548) -> 41.248
A5: ='IV Computed'!B7 -> 48.11 | B5: ='IV Computed'!B7*'IV Computed'!A7 -> 14.433 | C5: ='IV Computed'!D7 -> 63.01 | D5: ='IV Computed'!D7*'IV Computed'!C7 -> 18.903 | E5: ='IV Computed'!F7 -> 80.35 | F5: ='IV Computed'!F7*'IV Computed'!E7 -> 24.105 | G5: ='IV Computed'!H7 -> 97.82 | H5: ='IV Computed'!H7*'IV Computed'!G7 -> 29.346 | I5: ='IV Computed'!J7 -> 114.81 | J5: ='IV Computed'!J7*'IV Computed'!I7 -> 34.443 | K5: ='IV Computed'!L7 -> 132.67 | L5: ='IV Computed'!L7*'IV Computed'!K7 -> 39.801 | M5: ='IV Computed'!N7 -> 151.09 | N5: ='IV Computed'!N7*'IV Computed'!M7 -> 45.327 | O5: ='IV Computed'!P7 -> 170.02 | P5: ='IV Computed'!P7*'IV Computed'!O7 -> 51.006 | Q5: ='IV Computed'!R7 -> 189.78 | R5: ='IV Computed'!R7*'IV Computed'!Q7 -> 56.934 | S5: ='IV Computed'!T7 -> 209.28 | T5: ='IV Computed'!T7*'IV Computed'!S7 -> 62.784 | U5: ='IV Computed'!V7 -> 229.75 | V5: ='IV Computed'!V7*'IV Computed'!U7 -> 68.925 | W5: ='IV Computed'!X7 -> 251.76 | X5: ='IV Computed'!X7*'IV Computed'!W7 -> 75.528 | Y5: ='IV Computed'!Z7 -> 273.55 | Z5: ='IV Computed'!Z7*'IV Computed'!Y7 -> 82.065 | AA5: ='IV Computed'!AB7 -> 295.5 | AB5: ='IV Computed'!AB7*'IV Computed'!AA7 -> 88.65 | AC5: ='IV Computed'!AD7 -> 318.88 | AD5: ='IV Computed'!AD7*'IV Computed'!AC7 -> 95.664 | AE5: ='IV Computed'!AF7 -> 341.08 | AF5: ='IV Computed'!AF7*'IV Computed'!AE7 -> 102.324 | AG5: ='IV Computed'!AH7 -> 364.08 | AH5: ='IV Computed'!AH7*'IV Computed'!AG7 -> 109.224 | AI5: ='IV Computed'!AJ7 -> 386.28 | AJ5: ='IV Computed'!AJ7*'IV Computed'!AI7 -> 115.884 | AK5: ='IV Computed'!AL7 -> 408.35 | AL5: ='IV Computed'!AL7*'IV Computed'!AK7 -> 122.505 | AM5: ='IV Computed'!AN7 -> 427.53 | AN5: ='IV Computed'!AN7*'IV Computed'!AM7 -> 128.259 | AO5: ='IV Computed'!AP7 -> 442.22 | AP5: ='IV Computed'!AP7*'IV Computed'!AO7 -> 132.666 | AQ5: ='IV Computed'!AR7 -> 451.16 | AR5: ='IV Computed'!AR7*'IV Computed'!AQ7 -> 135.348 | AS5: ='IV Computed'!AT7 -> 457.97 | AT5: ='IV Computed'!AT7*'IV Computed'!AS7 -> 137.391 | AU5: ='IV Computed'!AV7 -> 462.92 | AV5: ='IV Computed'!AV7*'IV Computed'!AU7 -> 138.876 | AW5: ='IV Computed'!AX7 -> 467.29 | AX5: ='IV Computed'!AX7*'IV Computed'!AW7 -> 140.187 | AY5: ='IV Computed'!AZ7 -> 471.9 | AZ5: ='IV Computed'!AZ7*'IV Computed'!AY7 -> 141.57 | BC5: 3 | BD5: 32.88 | BE5: =MAX(D2:D548) -> 82.2
A6: ='IV Computed'!B8 -> 46.4 | B6: ='IV Computed'!B8*'IV Computed'!A8 -> 18.56 | C6: ='IV Computed'!D8 -> 61.64 | D6: ='IV Computed'!D8*'IV Computed'!C8 -> 24.656 | E6: ='IV Computed'!F8 -> 79.21 | F6: ='IV Computed'!F8*'IV Computed'!E8 -> 31.684 | G6: ='IV Computed'!H8 -> 96.79 | H6: ='IV Computed'!H8*'IV Computed'!G8 -> 38.716 | I6: ='IV Computed'!J8 -> 113.82 | J6: ='IV Computed'!J8*'IV Computed'!I8 -> 45.528 | K6: ='IV Computed'!L8 -> 131.71 | L6: ='IV Computed'!L8*'IV Computed'!K8 -> 52.684 | M6: ='IV Computed'!N8 -> 150.16 | N6: ='IV Computed'!N8*'IV Computed'!M8 -> 60.064 | O6: ='IV Computed'!P8 -> 169.11 | P6: ='IV Computed'!P8*'IV Computed'!O8 -> 67.644 | Q6: ='IV Computed'!R8 -> 188.89 | R6: ='IV Computed'!R8*'IV Computed'!Q8 -> 75.556 | S6: ='IV Computed'!T8 -> 208.39 | T6: ='IV Computed'!T8*'IV Computed'!S8 -> 83.356 | U6: ='IV Computed'!V8 -> 228.87 | V6: ='IV Computed'!V8*'IV Computed'!U8 -> 91.548 | W6: ='IV Computed'!X8 -> 250.89 | X6: ='IV Computed'!X8*'IV Computed'!W8 -> 100.356 | Y6: ='IV Computed'!Z8 -> 272.69 | Z6: ='IV Computed'!Z8*'IV Computed'!Y8 -> 109.076 | AA6: ='IV Computed'!AB8 -> 294.64 | AB6: ='IV Computed'!AB8*'IV Computed'!AA8 -> 117.856 | AC6: ='IV Computed'!AD8 -> 318.03 | AD6: ='IV Computed'!AD8*'IV Computed'!AC8 -> 127.212 | AE6: ='IV Computed'!AF8 -> 340.24 | AF6: ='IV Computed'!AF8*'IV Computed'!AE8 -> 136.096 | AG6: ='IV Computed'!AH8 -> 363.23 | AH6: ='IV Computed'!AH8*'IV Computed'!AG8 -> 145.292 | AI6: ='IV Computed'!AJ8 -> 385.44 | AJ6: ='IV Computed'!AJ8*'IV Computed'!AI8 -> 154.176 | AK6: ='IV Computed'!AL8 -> 407.51 | AL6: ='IV Computed'!AL8*'IV Computed'!AK8 -> 163.004 | AM6: ='IV Computed'!AN8 -> 426.69 | AN6: ='IV Computed'!AN8*'IV Computed'!AM8 -> 170.676 | AO6: ='IV Computed'!AP8 -> 441.37 | AP6: ='IV Computed'!AP8*'IV Computed'!AO8 -> 176.548 | AQ6: ='IV Computed'!AR8 -> 450.31 | AR6: ='IV Computed'!AR8*'IV Computed'!AQ8 -> 180.124 | AS6: ='IV Computed'!AT8 -> 457.12 | AT6: ='IV Computed'!AT8*'IV Computed'!AS8 -> 182.848 | AU6: ='IV Computed'!AV8 -> 462.07 | AV6: ='IV Computed'!AV8*'IV Computed'!AU8 -> 184.828 | AW6: ='IV Computed'!AX8 -> 466.43 | AX6: ='IV Computed'!AX8*'IV Computed'!AW8 -> 186.572 | AY6: ='IV Computed'!AZ8 -> 471.03 | AZ6: ='IV Computed'!AZ8*'IV Computed'!AY8 -> 188.412 | BC6: 3.5 | BD6: 41.87 | BE6: =MAX(F2:F548) -> 154.919
A7: ='IV Computed'!B9 -> 44.68 | B7: ='IV Computed'!B9*'IV Computed'!A9 -> 22.34 | C7: ='IV Computed'!D9 -> 60.27 | D7: ='IV Computed'!D9*'IV Computed'!C9 -> 30.135 | E7: ='IV Computed'!F9 -> 78.08 | F7: ='IV Computed'!F9*'IV Computed'!E9 -> 39.04 | G7: ='IV Computed'!H9 -> 95.76 | H7: ='IV Computed'!H9*'IV Computed'!G9 -> 47.88 | I7: ='IV Computed'!J9 -> 112.83 | J7: ='IV Computed'!J9*'IV Computed'!I9 -> 56.415 | K7: ='IV Computed'!L9 -> 130.76 | L7: ='IV Computed'!L9*'IV Computed'!K9 -> 65.38 | M7: ='IV Computed'!N9 -> 149.24 | N7: ='IV Computed'!N9*'IV Computed'!M9 -> 74.62 | O7: ='IV Computed'!P9 -> 168.2 | P7: ='IV Computed'!P9*'IV Computed'!O9 -> 84.1 | Q7: ='IV Computed'!R9 -> 187.99 | R7: ='IV Computed'!R9*'IV Computed'!Q9 -> 93.995 | S7: ='IV Computed'!T9 -> 207.51 | T7: ='IV Computed'!T9*'IV Computed'!S9 -> 103.755 | U7: ='IV Computed'!V9 -> 228 | V7: ='IV Computed'!V9*'IV Computed'!U9 -> 114 | W7: ='IV Computed'!X9 -> 250.02 | X7: ='IV Computed'!X9*'IV Computed'!W9 -> 125.01 | Y7: ='IV Computed'!Z9 -> 271.83 | Z7: ='IV Computed'!Z9*'IV Computed'!Y9 -> 135.915 | AA7: ='IV Computed'!AB9 -> 293.79 | AB7: ='IV Computed'!AB9*'IV Computed'!AA9 -> 146.895 | AC7: ='IV Computed'!AD9 -> 317.18 | AD7: ='IV Computed'!AD9*'IV Computed'!AC9 -> 158.59 | AE7: ='IV Computed'!AF9 -> 339.39 | AF7: ='IV Computed'!AF9*'IV Computed'!AE9 -> 169.695 | AG7: ='IV Computed'!AH9 -> 362.39 | AH7: ='IV Computed'!AH9*'IV Computed'!AG9 -> 181.195 | AI7: ='IV Computed'!AJ9 -> 384.59 | AJ7: ='IV Computed'!AJ9*'IV Computed'!AI9 -> 192.295 | AK7: ='IV Computed'!AL9 -> 406.66 | AL7: ='IV Computed'!AL9*'IV Computed'!AK9 -> 203.33 | AM7: ='IV Computed'!AN9 -> 425.84 | AN7: ='IV Computed'!AN9*'IV Computed'!AM9 -> 212.92 | AO7: ='IV Computed'!AP9 -> 440.53 | AP7: ='IV Computed'!AP9*'IV Computed'!AO9 -> 220.265 | AQ7: ='IV Computed'!AR9 -> 449.47 | AR7: ='IV Computed'!AR9*'IV Computed'!AQ9 -> 224.735 | AS7: ='IV Computed'!AT9 -> 456.26 | AT7: ='IV Computed'!AT9*'IV Computed'!AS9 -> 228.13 | AU7: ='IV Computed'!AV9 -> 461.21 | AV7: ='IV Computed'!AV9*'IV Computed'!AU9 -> 230.605 | AW7: ='IV Computed'!AX9 -> 465.57 | AX7: ='IV Computed'!AX9*'IV Computed'!AW9 -> 232.785 | AY7: ='IV Computed'!AZ9 -> 470.16 | AZ7: ='IV Computed'!AZ9*'IV Computed'!AY9 -> 235.08 | BC7: 4 | BD7: 50.46 | BE7: =MAX(H2:H548) -> 247.254
A8: ='IV Computed'!B10 -> 42.96 | B8: ='IV Computed'!B10*'IV Computed'!A10 -> 25.776 | C8: ='IV Computed'!D10 -> 58.9 | D8: ='IV Computed'!D10*'IV Computed'!C10 -> 35.34 | E8: ='IV Computed'!F10 -> 76.95 | F8: ='IV Computed'!F10*'IV Computed'!E10 -> 46.17 | G8: ='IV Computed'!H10 -> 94.73 | H8: ='IV Computed'!H10*'IV Computed'!G10 -> 56.838 | I8: ='IV Computed'!J10 -> 111.84 | J8: ='IV Computed'!J10*'IV Computed'!I10 -> 67.104 | K8: ='IV Computed'!L10 -> 129.8 | L8: ='IV Computed'!L10*'IV Computed'!K10 -> 77.88 | M8: ='IV Computed'!N10 -> 148.31 | N8: ='IV Computed'!N10*'IV Computed'!M10 -> 88.986 | O8: ='IV Computed'!P10 -> 167.29 | P8: ='IV Computed'!P10*'IV Computed'!O10 -> 100.374 | Q8: ='IV Computed'!R10 -> 187.1 | R8: ='IV Computed'!R10*'IV Computed'!Q10 -> 112.26 | S8: ='IV Computed'!T10 -> 206.62 | T8: ='IV Computed'!T10*'IV Computed'!S10 -> 123.972 | U8: ='IV Computed'!V10 -> 227.12 | V8: ='IV Computed'!V10*'IV Computed'!U10 -> 136.272 | W8: ='IV Computed'!X10 -> 249.15 | X8: ='IV Computed'!X10*'IV Computed'!W10 -> 149.49 | Y8: ='IV Computed'!Z10 -> 270.97 | Z8: ='IV Computed'!Z10*'IV Computed'!Y10 -> 162.582 | AA8: ='IV Computed'!AB10 -> 292.93 | AB8: ='IV Computed'!AB10*'IV Computed'!AA10 -> 175.758 | AC8: ='IV Computed'!AD10 -> 316.32 | AD8: ='IV Computed'!AD10*'IV Computed'!AC10 -> 189.792 | AE8: ='IV Computed'!AF10 -> 338.54 | AF8: ='IV Computed'!AF10*'IV Computed'!AE10 -> 203.124 | AG8: ='IV Computed'!AH10 -> 361.54 | AH8: ='IV Computed'!AH10*'IV Computed'!AG10 -> 216.924 | AI8: ='IV Computed'!AJ10 -> 383.75 | AJ8: ='IV Computed'!AJ10*'IV Computed'!AI10 -> 230.25 | AK8: ='IV Computed'!AL10 -> 405.82 | AL8: ='IV Computed'!AL10*'IV Computed'!AK10 -> 243.492 | AM8: ='IV Computed'!AN10 -> 425 | AN8: ='IV Computed'!AN10*'IV Computed'!AM10 -> 255 | AO8: ='IV Computed'!AP10 -> 439.69 | AP8: ='IV Computed'!AP10*'IV Computed'!AO10 -> 263.814 | AQ8: ='IV Computed'!AR10 -> 448.62 | AR8: ='IV Computed'!AR10*'IV Computed'!AQ10 -> 269.172 | AS8: ='IV Computed'!AT10 -> 455.41 | AT8: ='IV Computed'!AT10*'IV Computed'!AS10 -> 273.246 | AU8: ='IV Computed'!AV10 -> 460.36 | AV8: ='IV Computed'!AV10*'IV Computed'!AU10 -> 276.216 | AW8: ='IV Computed'!AX10 -> 464.71 | AX8: ='IV Computed'!AX10*'IV Computed'!AW10 -> 278.826 | AY8: ='IV Computed'!AZ10 -> 469.3 | AZ8: ='IV Computed'!AZ10*'IV Computed'!AY10 -> 281.58 | BC8: 4.5 | BD8: 58.4 | BE8: =MAX(J2:J548) -> 350.4
A9: ='IV Computed'!B11 -> 41.24 | B9: ='IV Computed'!B11*'IV Computed'!A11 -> 28.868 | C9: ='IV Computed'!D11 -> 57.53 | D9: ='IV Computed'!D11*'IV Computed'!C11 -> 40.271 | E9: ='IV Computed'!F11 -> 75.82 | F9: ='IV Computed'!F11*'IV Computed'!E11 -> 53.074 | G9: ='IV Computed'!H11 -> 93.7 | H9: ='IV Computed'!H11*'IV Computed'!G11 -> 65.59 | I9: ='IV Computed'!J11 -> 110.85 | J9: ='IV Computed'!J11*'IV Computed'!I11 -> 77.595 | K9: ='IV Computed'!L11 -> 128.85 | L9: ='IV Computed'!L11*'IV Computed'!K11 -> 90.195 | M9: ='IV Computed'!N11 -> 147.38 | N9: ='IV Computed'!N11*'IV Computed'!M11 -> 103.166 | O9: ='IV Computed'!P11 -> 166.39 | P9: ='IV Computed'!P11*'IV Computed'!O11 -> 116.473 | Q9: ='IV Computed'!R11 -> 186.2 | R9: ='IV Computed'!R11*'IV Computed'!Q11 -> 130.34 | S9: ='IV Computed'!T11 -> 205.73 | T9: ='IV Computed'!T11*'IV Computed'!S11 -> 144.011 | U9: ='IV Computed'!V11 -> 226.24 | V9: ='IV Computed'!V11*'IV Computed'!U11 -> 158.368 | W9: ='IV Computed'!X11 -> 248.28 | X9: ='IV Computed'!X11*'IV Computed'!W11 -> 173.796 | Y9: ='IV Computed'!Z11 -> 270.11 | Z9: ='IV Computed'!Z11*'IV Computed'!Y11 -> 189.077 | AA9: ='IV Computed'!AB11 -> 292.07 | AB9: ='IV Computed'!AB11*'IV Computed'!AA11 -> 204.449 | AC9: ='IV Computed'!AD11 -> 315.47 | AD9: ='IV Computed'!AD11*'IV Computed'!AC11 -> 220.829 | AE9: ='IV Computed'!AF11 -> 337.69 | AF9: ='IV Computed'!AF11*'IV Computed'!AE11 -> 236.383 | AG9: ='IV Computed'!AH11 -> 360.69 | AH9: ='IV Computed'!AH11*'IV Computed'!AG11 -> 252.483 | AI9: ='IV Computed'!AJ11 -> 382.9 | AJ9: ='IV Computed'!AJ11*'IV Computed'!AI11 -> 268.03 | AK9: ='IV Computed'!AL11 -> 404.97 | AL9: ='IV Computed'!AL11*'IV Computed'!AK11 -> 283.479 | AM9: ='IV Computed'!AN11 -> 424.16 | AN9: ='IV Computed'!AN11*'IV Computed'!AM11 -> 296.912 | AO9: ='IV Computed'!AP11 -> 438.84 | AP9: ='IV Computed'!AP11*'IV Computed'!AO11 -> 307.188 | AQ9: ='IV Computed'!AR11 -> 447.77 | AR9: ='IV Computed'!AR11*'IV Computed'!AQ11 -> 313.439 | AS9: ='IV Computed'!AT11 -> 454.56 | AT9: ='IV Computed'!AT11*'IV Computed'!AS11 -> 318.192 | AU9: ='IV Computed'!AV11 -> 459.5 | AV9: ='IV Computed'!AV11*'IV Computed'!AU11 -> 321.65 | AW9: ='IV Computed'!AX11 -> 463.84 | AX9: ='IV Computed'!AX11*'IV Computed'!AW11 -> 324.688 | AY9: ='IV Computed'!AZ11 -> 468.43 | AZ9: ='IV Computed'!AZ11*'IV Computed'!AY11 -> 327.901 | BC9: 5 | BD9: 67.76 | BE9: =MAX(L2:L548) -> 481.096
A10: ='IV Computed'!B12 -> 39.52 | B10: ='IV Computed'!B12*'IV Computed'!A12 -> 31.616 | C10: ='IV Computed'!D12 -> 56.16 | D10: ='IV Computed'!D12*'IV Computed'!C12 -> 44.928 | E10: ='IV Computed'!F12 -> 74.69 | F10: ='IV Computed'!F12*'IV Computed'!E12 -> 59.752 | G10: ='IV Computed'!H12 -> 92.67 | H10: ='IV Computed'!H12*'IV Computed'!G12 -> 74.136 | I10: ='IV Computed'!J12 -> 109.86 | J10: ='IV Computed'!J12*'IV Computed'!I12 -> 87.888 | K10: ='IV Computed'!L12 -> 127.89 | L10: ='IV Computed'!L12*'IV Computed'!K12 -> 102.312 | M10: ='IV Computed'!N12 -> 146.45 | N10: ='IV Computed'!N12*'IV Computed'!M12 -> 117.16 | O10: ='IV Computed'!P12 -> 165.48 | P10: ='IV Computed'!P12*'IV Computed'!O12 -> 132.384 | Q10: ='IV Computed'!R12 -> 185.31 | R10: ='IV Computed'!R12*'IV Computed'!Q12 -> 148.248 | S10: ='IV Computed'!T12 -> 204.85 | T10: ='IV Computed'!T12*'IV Computed'!S12 -> 163.88 | U10: ='IV Computed'!V12 -> 225.36 | V10: ='IV Computed'!V12*'IV Computed'!U12 -> 180.288 | W10: ='IV Computed'!X12 -> 247.42 | X10: ='IV Computed'!X12*'IV Computed'!W12 -> 197.936 | Y10: ='IV Computed'!Z12 -> 269.25 | Z10: ='IV Computed'!Z12*'IV Computed'!Y12 -> 215.4 | AA10: ='IV Computed'!AB12 -> 291.22 | AB10: ='IV Computed'!AB12*'IV Computed'!AA12 -> 232.976 | AC10: ='IV Computed'!AD12 -> 314.62 | AD10: ='IV Computed'!AD12*'IV Computed'!AC12 -> 251.696 | AE10: ='IV Computed'!AF12 -> 336.84 | AF10: ='IV Computed'!AF12*'IV Computed'!AE12 -> 269.472 | AG10: ='IV Computed'!AH12 -> 359.85 | AH10: ='IV Computed'!AH12*'IV Computed'!AG12 -> 287.88 | AI10: ='IV Computed'!AJ12 -> 382.06 | AJ10: ='IV Computed'!AJ12*'IV Computed'!AI12 -> 305.648 | AK10: ='IV Computed'!AL12 -> 404.13 | AL10: ='IV Computed'!AL12*'IV Computed'!AK12 -> 323.304 | AM10: ='IV Computed'!AN12 -> 423.31 | AN10: ='IV Computed'!AN12*'IV Computed'!AM12 -> 338.648 | AO10: ='IV Computed'!AP12 -> 438 | AP10: ='IV Computed'!AP12*'IV Computed'!AO12 -> 350.4 | AQ10: ='IV Computed'!AR12 -> 446.93 | AR10: ='IV Computed'!AR12*'IV Computed'!AQ12 -> 357.544 | AS10: ='IV Computed'!AT12 -> 453.71 | AT10: ='IV Computed'!AT12*'IV Computed'!AS12 -> 362.968 | AU10: ='IV Computed'!AV12 -> 458.64 | AV10: ='IV Computed'!AV12*'IV Computed'!AU12 -> 366.912 | AW10: ='IV Computed'!AX12 -> 462.98 | AX10: ='IV Computed'!AX12*'IV Computed'!AW12 -> 370.384 | AY10: ='IV Computed'!AZ12 -> 467.56 | AZ10: ='IV Computed'!AZ12*'IV Computed'!AY12 -> 374.048 | BC10: 5.5 | BD10: 76.94 | BE10: =MAX(N2:N548) -> 638.602
A11: ='IV Computed'!B13 -> 37.8 | B11: ='IV Computed'!B13*'IV Computed'!A13 -> 34.02 | C11: ='IV Computed'!D13 -> 54.79 | D11: ='IV Computed'!D13*'IV Computed'!C13 -> 49.311 | E11: ='IV Computed'!F13 -> 73.56 | F11: ='IV Computed'!F13*'IV Computed'!E13 -> 66.204 | G11: ='IV Computed'!H13 -> 91.64 | H11: ='IV Computed'!H13*'IV Computed'!G13 -> 82.476 | I11: ='IV Computed'!J13 -> 108.87 | J11: ='IV Computed'!J13*'IV Computed'!I13 -> 97.983 | K11: ='IV Computed'!L13 -> 126.94 | L11: ='IV Computed'!L13*'IV Computed'!K13 -> 114.246 | M11: ='IV Computed'!N13 -> 145.53 | N11: ='IV Computed'!N13*'IV Computed'!M13 -> 130.977 | O11: ='IV Computed'!P13 -> 164.57 | P11: ='IV Computed'!P13*'IV Computed'!O13 -> 148.113 | Q11: ='IV Computed'!R13 -> 184.41 | R11: ='IV Computed'!R13*'IV Computed'!Q13 -> 165.969 | S11: ='IV Computed'!T13 -> 203.96 | T11: ='IV Computed'!T13*'IV Computed'!S13 -> 183.564 | U11: ='IV Computed'!V13 -> 224.49 | V11: ='IV Computed'!V13*'IV Computed'!U13 -> 202.041 | W11: ='IV Computed'!X13 -> 246.55 | X11: ='IV Computed'!X13*'IV Computed'!W13 -> 221.895 | Y11: ='IV Computed'!Z13 -> 268.39 | Z11: ='IV Computed'!Z13*'IV Computed'!Y13 -> 241.551 | AA11: ='IV Computed'!AB13 -> 290.36 | AB11: ='IV Computed'!AB13*'IV Computed'!AA13 -> 261.324 | AC11: ='IV Computed'!AD13 -> 313.77 | AD11: ='IV Computed'!AD13*'IV Computed'!AC13 -> 282.393 | AE11: ='IV Computed'!AF13 -> 335.99 | AF11: ='IV Computed'!AF13*'IV Computed'!AE13 -> 302.391 | AG11: ='IV Computed'!AH13 -> 359 | AH11: ='IV Computed'!AH13*'IV Computed'!AG13 -> 323.1 | AI11: ='IV Computed'!AJ13 -> 381.21 | AJ11: ='IV Computed'!AJ13*'IV Computed'!AI13 -> 343.089 | AK11: ='IV Computed'!AL13 -> 403.29 | AL11: ='IV Computed'!AL13*'IV Computed'!AK13 -> 362.961 | AM11: ='IV Computed'!AN13 -> 422.47 | AN11: ='IV Computed'!AN13*'IV Computed'!AM13 -> 380.223 | AO11: ='IV Computed'!AP13 -> 437.15 | AP11: ='IV Computed'!AP13*'IV Computed'!AO13 -> 393.435 | AQ11: ='IV Computed'!AR13 -> 446.08 | AR11: ='IV Computed'!AR13*'IV Computed'!AQ13 -> 401.472 | AS11: ='IV Computed'!AT13 -> 452.86 | AT11: ='IV Computed'!AT13*'IV Computed'!AS13 -> 407.574 | AU11: ='IV Computed'!AV13 -> 457.79 | AV11: ='IV Computed'!AV13*'IV Computed'!AU13 -> 412.011 | AW11: ='IV Computed'!AX13 -> 462.12 | AX11: ='IV Computed'!AX13*'IV Computed'!AW13 -> 415.908 | AY11: ='IV Computed'!AZ13 -> 466.69 | AZ11: ='IV Computed'!AZ13*'IV Computed'!AY13 -> 420.021 | BC11: 6 | BD11: 86.37 | BE11: =MAX(P2:P548) -> 820.515
A12: ='IV Computed'!B14 -> 36.09 | B12: ='IV Computed'!B14*'IV Computed'!A14 -> 36.09 | C12: ='IV Computed'!D14 -> 53.42 | D12: ='IV Computed'!D14*'IV Computed'!C14 -> 53.42 | E12: ='IV Computed'!F14 -> 72.42 | F12: ='IV Computed'!F14*'IV Computed'!E14 -> 72.42 | G12: ='IV Computed'!H14 -> 90.61 | H12: ='IV Computed'!H14*'IV Computed'!G14 -> 90.61 | I12: ='IV Computed'!J14 -> 107.88 | J12: ='IV Computed'!J14*'IV Computed'!I14 -> 107.88 | K12: ='IV Computed'!L14 -> 125.99 | L12: ='IV Computed'!L14*'IV Computed'!K14 -> 125.99 | M12: ='IV Computed'!N14 -> 144.6 | N12: ='IV Computed'!N14*'IV Computed'!M14 -> 144.6 | O12: ='IV Computed'!P14 -> 163.66 | P12: ='IV Computed'!P14*'IV Computed'!O14 -> 163.66 | Q12: ='IV Computed'!R14 -> 183.52 | R12: ='IV Computed'!R14*'IV Computed'!Q14 -> 183.52 | S12: ='IV Computed'!T14 -> 203.07 | T12: ='IV Computed'!T14*'IV Computed'!S14 -> 203.07 | U12: ='IV Computed'!V14 -> 223.61 | V12: ='IV Computed'!V14*'IV Computed'!U14 -> 223.61 | W12: ='IV Computed'!X14 -> 245.68 | X12: ='IV Computed'!X14*'IV Computed'!W14 -> 245.68 | Y12: ='IV Computed'!Z14 -> 267.53 | Z12: ='IV Computed'!Z14*'IV Computed'!Y14 -> 267.53 | AA12: ='IV Computed'!AB14 -> 289.5 | AB12: ='IV Computed'!AB14*'IV Computed'!AA14 -> 289.5 | AC12: ='IV Computed'!AD14 -> 312.91 | AD12: ='IV Computed'!AD14*'IV Computed'!AC14 -> 312.91 | AE12: ='IV Computed'!AF14 -> 335.15 | AF12: ='IV Computed'!AF14*'IV Computed'!AE14 -> 335.15 | AG12: ='IV Computed'!AH14 -> 358.15 | AH12: ='IV Computed'!AH14*'IV Computed'!AG14 -> 358.15 | AI12: ='IV Computed'!AJ14 -> 380.37 | AJ12: ='IV Computed'!AJ14*'IV Computed'!AI14 -> 380.37 | AK12: ='IV Computed'!AL14 -> 402.44 | AL12: ='IV Computed'!AL14*'IV Computed'!AK14 -> 402.44 | AM12: ='IV Computed'!AN14 -> 421.63 | AN12: ='IV Computed'!AN14*'IV Computed'!AM14 -> 421.63 | AO12: ='IV Computed'!AP14 -> 436.31 | AP12: ='IV Computed'!AP14*'IV Computed'!AO14 -> 436.31 | AQ12: ='IV Computed'!AR14 -> 445.24 | AR12: ='IV Computed'!AR14*'IV Computed'!AQ14 -> 445.24 | AS12: ='IV Computed'!AT14 -> 452.01 | AT12: ='IV Computed'!AT14*'IV Computed'!AS14 -> 452.01 | AU12: ='IV Computed'!AV14 -> 456.93 | AV12: ='IV Computed'!AV14*'IV Computed'!AU14 -> 456.93 | AW12: ='IV Computed'!AX14 -> 461.26 | AX12: ='IV Computed'!AX14*'IV Computed'!AW14 -> 461.26 | AY12: ='IV Computed'!AZ14 -> 465.82 | AZ12: ='IV Computed'!AZ14*'IV Computed'!AY14 -> 465.82 | BC12: 6.5 | BD12: 95.79 | BE12: =MAX(R2:R548) -> 1034.532
A13: ='IV Computed'!B15 -> 34.37 | B13: ='IV Computed'!B15*'IV Computed'!A15 -> 37.807 | C13: ='IV Computed'!D15 -> 52.05 | D13: ='IV Computed'!D15*'IV Computed'!C15 -> 57.255 | E13: ='IV Computed'!F15 -> 71.29 | F13: ='IV Computed'!F15*'IV Computed'!E15 -> 78.419 | G13: ='IV Computed'!H15 -> 89.58 | H13: ='IV Computed'!H15*'IV Computed'!G15 -> 98.538 | I13: ='IV Computed'!J15 -> 106.89 | J13: ='IV Computed'!J15*'IV Computed'!I15 -> 117.579 | K13: ='IV Computed'!L15 -> 125.03 | L13: ='IV Computed'!L15*'IV Computed'!K15 -> 137.533 | M13: ='IV Computed'!N15 -> 143.67 | N13: ='IV Computed'!N15*'IV Computed'!M15 -> 158.037 | O13: ='IV Computed'!P15 -> 162.75 | P13: ='IV Computed'!P15*'IV Computed'!O15 -> 179.025 | Q13: ='IV Computed'!R15 -> 182.62 | R13: ='IV Computed'!R15*'IV Computed'!Q15 -> 200.882 | S13: ='IV Computed'!T15 -> 202.19 | T13: ='IV Computed'!T15*'IV Computed'!S15 -> 222.409 | U13: ='IV Computed'!V15 -> 222.73 | V13: ='IV Computed'!V15*'IV Computed'!U15 -> 245.003 | W13: ='IV Computed'!X15 -> 244.81 | X13: ='IV Computed'!X15*'IV Computed'!W15 -> 269.291 | Y13: ='IV Computed'!Z15 -> 266.67 | Z13: ='IV Computed'!Z15*'IV Computed'!Y15 -> 293.337 | AA13: ='IV Computed'!AB15 -> 288.65 | AB13: ='IV Computed'!AB15*'IV Computed'!AA15 -> 317.515 | AC13: ='IV Computed'!AD15 -> 312.06 | AD13: ='IV Computed'!AD15*'IV Computed'!AC15 -> 343.266 | AE13: ='IV Computed'!AF15 -> 334.3 | AF13: ='IV Computed'!AF15*'IV Computed'!AE15 -> 367.73 | AG13: ='IV Computed'!AH15 -> 357.31 | AH13: ='IV Computed'!AH15*'IV Computed'!AG15 -> 393.041 | AI13: ='IV Computed'!AJ15 -> 379.52 | AJ13: ='IV Computed'!AJ15*'IV Computed'!AI15 -> 417.472 | AK13: ='IV Computed'!AL15 -> 401.6 | AL13: ='IV Computed'!AL15*'IV Computed'!AK15 -> 441.76 | AM13: ='IV Computed'!AN15 -> 420.78 | AN13: ='IV Computed'!AN15*'IV Computed'!AM15 -> 462.858 | AO13: ='IV Computed'!AP15 -> 435.47 | AP13: ='IV Computed'!AP15*'IV Computed'!AO15 -> 479.017 | AQ13: ='IV Computed'!AR15 -> 444.39 | AR13: ='IV Computed'!AR15*'IV Computed'!AQ15 -> 488.829 | AS13: ='IV Computed'!AT15 -> 451.16 | AT13: ='IV Computed'!AT15*'IV Computed'!AS15 -> 496.276 | AU13: ='IV Computed'!AV15 -> 456.08 | AV13: ='IV Computed'!AV15*'IV Computed'!AU15 -> 501.688 | AW13: ='IV Computed'!AX15 -> 460.4 | AX13: ='IV Computed'!AX15*'IV Computed'!AW15 -> 506.44 | AY13: ='IV Computed'!AZ15 -> 464.95 | AZ13: ='IV Computed'!AZ15*'IV Computed'!AY15 -> 511.445 | BC13: 7 | BD13: 105.53 | BE13: =MAX(T2:T548) -> 1266.36
